Workbook
Name SKU_1: Lists!$A$2:$A$2
Name SKU_10: Lists!$J$2:$J$2
Name SKU_11: Lists!$K$2:$K$2
Name SKU_12: Lists!$L$2:$L$3
Name SKU_13: Lists!$M$2:$M$2
Name SKU_14: Lists!$N$2:$N$2
Name SKU_15: Lists!$O$2:$O$2
Name SKU_16: Lists!$P$2:$P$2
Name SKU_17: Lists!$Q$2:$Q$2
Name SKU_18: Lists!$R$2:$R$2
Name SKU_19: Lists!$S$2:$S$2
Name SKU_2: Lists!$B$2:$B$2
Name SKU_20: Lists!$T$2:$T$3
Name SKU_21: Lists!$U$2:$U$2
Name SKU_22: Lists!$V$2:$V$3
Name SKU_23: Lists!$W$2:$W$3
Name SKU_24: Lists!$X$2:$X$4
Name SKU_25: Lists!$Y$2:$Y$2
Name SKU_26: Lists!$Z$2:$Z$2
Name SKU_27: Lists!$AA$2:$AA$3
Name SKU_28: Lists!$AB$2:$AB$3
Name SKU_29: Lists!$AC$2:$AC$2
Name SKU_3: Lists!$C$2:$C$2
Name SKU_30: Lists!$AD$2:$AD$4
Name SKU_31: Lists!$AE$2:$AE$4
Name SKU_32: Lists!$AF$2:$AF$2
Name SKU_33: Lists!$AG$2:$AG$4
Name SKU_34: Lists!$AH$2:$AH$2
Name SKU_35: Lists!$AI$2:$AI$2
Name SKU_36: Lists!$AJ$2:$AJ$2
Name SKU_37: Lists!$AK$2:$AK$3
Name SKU_38: Lists!$AL$2:$AL$2
Name SKU_39: Lists!$AM$2:$AM$2
Name SKU_4: Lists!$D$2:$D$15
Name SKU_40: Lists!$AN$2:$AN$3
Name SKU_41: Lists!$AO$2:$AO$4
Name SKU_42: Lists!$AP$2:$AP$2
Name SKU_43: Lists!$AQ$2:$AQ$2
Name SKU_44: Lists!$AR$2:$AR$3
Name SKU_45: Lists!$AS$2:$AS$4
Name SKU_46: Lists!$AT$2:$AT$4
Name SKU_47: Lists!$AU$2:$AU$2
Name SKU_48: Lists!$AV$2:$AV$2
Name SKU_49: Lists!$AW$2:$AW$3
Name SKU_5: Lists!$E$2:$E$4
Name SKU_50: Lists!$AX$2:$AX$2
Name SKU_51: Lists!$AY$2:$AY$2
Name SKU_52: Lists!$AZ$2:$AZ$2
Name SKU_53: Lists!$BA$2:$BA$2
Name SKU_54: Lists!$BB$2:$BB$2
Name SKU_55: Lists!$BC$2:$BC$3
Name SKU_56: Lists!$BD$2:$BD$2
Name SKU_57: Lists!$BE$2:$BE$2
Name SKU_58: Lists!$BF$2:$BF$2
Name SKU_59: Lists!$BG$2:$BG$2
Name SKU_6: Lists!$F$2:$F$9
Name SKU_7: Lists!$G$2:$G$2
Name SKU_8: Lists!$H$2:$H$2
Name SKU_9: Lists!$I$2:$I$9

Sheet Start Here
A1: Unified Data Platform | Azure cost model & BOM
A3: Topic | B3: Instructions / interpretation
A4: Scope | B4: One workbook: tagged scripts\udp.yml + all 15 example configurations. Source snapshot 2026-10-19. All declared targets included; one target active per scenario.
A5: 1. Choose scenario / target | B5: Open a BOM tab, select target in B2, and optionally filter Target to that value. Scenario Summary links to every BOM; Category Summary separates infrastructure, security, storage, Fabric, AI and other known costs.
A6: 2. Select Fabric capacity | B6: Every capacity starts as SELECT SKU, as requested. Choose F2-F8192 in the Shared Fabric capacity row for your target. Capacity is an existing dependency, not deployed by these YAMLs.
A7: 3. Change sizing | B7: Yellow cells are editable. Select a capability-specific SKU; edit quantity, size/monthly usage and PAYG utilization. Units are shown per line. Quantity=0 excludes a line.
A8: 4. Compare purchase plans | B8: Assumptions B7 chooses PAYG / 1Y / 3Y. A line can override via Purchase plan. Eligible compute uses actual reservation prices; consumption-only services remain PAYG under all plans. Missing reservation prices remain UNPRICED.
A9: 5. Interpret results | B9: Known monthly subtotal is NOT a complete estimate when unpriced active lines > 0. INCOMPLETE is deliberate. Annual run rate = monthly x 12, not a cash payment schedule. Plan comparison columns each have their own gap count.
A10: 6. Recommended baseline | B10: User requested ENABLED: ADLS where absent, Key Vault where absent, Sentinel, monitoring, private endpoints/DNS, egress, Azure OpenAI token usage, AI Search and Defender for Storage V2 (quote required). Every added line says Recommended baseline. Assumptions B10=0 excludes ALL such rows.
A11: 7. Resolve gaps | B11: Missing SKU, exact meter or usage is UNPRICED, never a zero-cost fallback. Enter Manual monthly rate USD/unit with quote source in the row note. Override rate is already normalized to the displayed monthly size unit; it bypasses utilization and is held constant in all plan comparisons. Remove it to resume SKU-derived pricing.
A12: Capacity accounting | B12: Compute pool billed ONCE per selected scenario. Fabric items (notebooks, Spark, pipelines, eventhouses, BI, data agents) appear in inventory as covered compute, not individual charges. OneLake is a pooled physical storage assumption. External Azure services billed separately.
A13: Capacity caveats | B13: Baseline CU price comes from the official Compute Pool Capacity Usage CU meter; reservation CU totals multiplied by SKU CUs. Validate F-SKU sizing/availability with Fabric estimator and your agreement. Opt-in Spark autoscale, overages and workload-specific serverless charges are NOT covered by reserved/shared capacity and require additional allowance.
A14: Reservation math | B14: 1Y total / 12; 3Y total / 36. Reserved compute is fully committed even when PAYG utilization <100%. No assumed discount or automatic substitution. DBU commitments, savings plans and storage reservations are not modeled.
... A27: Retail API documentation | B27: https://learn.microsoft.com/en-us/rest/api/cost-management/retail-prices/azure-retail-prices

Sheet Scenario Summary
A1: Unified Data Platform | scenario comparison
A2: Alternatives, NOT additive. Each subtotal excludes UNPRICED lines. Select Fabric SKU on each BOM to complete capacity costing.
A5: Scenario | B5: Selected target | C5: Known monthly subtotal (USD) | D5: Annual run rate (USD) | E5: Unpriced active lines | F5: Estimate status | G5: YAML / dependency USD | H5: Recommended baseline USD | I5: PAYG known subtotal USD | J5: 1Y known subtotal USD | K5: 3Y known subtotal USD | L5: PAYG gaps | M5: 1Y gaps | N5: 3Y gaps
A6: Base udp.yml | B6: ='Base udp.yml'!B2 -> prod | C6: ='Base udp.yml'!H2 -> 330.434 | D6: =C6*Assumptions!$B$8 -> 3965.208 | E6: ='Base udp.yml'!K2 -> 3 | F6: ='Base udp.yml'!N2 -> INCOMPLETE | G6: =SUMIFS('Base udp.yml'!O6:O26,'Base udp.yml'!C6:C26,"<>Recommended baseline") -> 0 | H6: =SUMIF('Base udp.yml'!C6:C26,"Recommended baseline",'Base udp.yml'!O6:O26) -> 330.434 | I6: =SUM('Base udp.yml'!V6:V26) -> 330.434 | J6: =SUM('Base udp.yml'!W6:W26) -> 330.434 | K6: =SUM('Base udp.yml'!X6:X26) -> 330.434 | L6: =COUNTIF('Base udp.yml'!V6:V26,"UNPRICED") -> 3 | M6: =COUNTIF('Base udp.yml'!W6:W26,"UNPRICED") -> 3 | N6: =COUNTIF('Base udp.yml'!X6:X26,"UNPRICED") -> 3
A7: BOM 00-default | B7: ='BOM 00-default'!B2 -> dev | C7: ='BOM 00-default'!H2 -> 12281.034 | D7: =C7*Assumptions!$B$8 -> 147372.41 | E7: ='BOM 00-default'!K2 -> 34 | F7: ='BOM 00-default'!N2 -> INCOMPLETE | G7: =SUMIFS('BOM 00-default'!O6:O1473,'BOM 00-default'!C6:C1473,"<>Recommended baseline") -> 12175.304 | H7: =SUMIF('BOM 00-default'!C6:C1473,"Recommended baseline",'BOM 00-default'!O6:O1473) -> 105.73 | I7: =SUM('BOM 00-default'!V6:V1473) -> 12281.034 | J7: =SUM('BOM 00-default'!W6:W1473) -> 8453.9874 | K7: =SUM('BOM 00-default'!X6:X1473) -> 8215.543 | L7: =COUNTIF('BOM 00-default'!V6:V1473,"UNPRICED") -> 34 | M7: =COUNTIF('BOM 00-default'!W6:W1473,"UNPRICED") -> 34 | N7: =COUNTIF('BOM 00-default'!X6:X1473,"UNPRICED") -> 34
A8: BOM 01-minimal | B8: ='BOM 01-minimal'!B2 -> dev | C8: ='BOM 01-minimal'!H2 -> 8766.658 | D8: =C8*Assumptions!$B$8 -> 105199.9 | E8: ='BOM 01-minimal'!K2 -> 2 | F8: ='BOM 01-minimal'!N2 -> INCOMPLETE | G8: =SUMIFS('BOM 01-minimal'!O6:O25,'BOM 01-minimal'!C6:C25,"<>Recommended baseline") -> 8436.224 | H8: =SUMIF('BOM 01-minimal'!C6:C25,"Recommended baseline",'BOM 01-minimal'!O6:O25) -> 330.434 | I8: =SUM('BOM 01-minimal'!V6:V25) -> 8766.658 | J8: =SUM('BOM 01-minimal'!W6:W25) -> 5359.7247 | K8: =SUM('BOM 01-minimal'!X6:X25) -> 5359.7247 | L8: =COUNTIF('BOM 01-minimal'!V6:V25,"UNPRICED") -> 2 | M8: =COUNTIF('BOM 01-minimal'!W6:W25,"UNPRICED") -> 2 | N8: =COUNTIF('BOM 01-minimal'!X6:X25,"UNPRICED") -> 2
A9: BOM 02-medallion-lakehouse | B9: ='BOM 02-medallion-lakehouse'!B2 -> dev | C9: ='BOM 02-medallion-lakehouse'!H2 -> 357.058 | D9: =C9*Assumptions!$B$8 -> 4284.696 | E9: ='BOM 02-medallion-lakehouse'!K2 -> 3 | F9: ='BOM 02-medallion-lakehouse'!N2 -> INCOMPLETE | G9: =SUMIFS('BOM 02-medallion-lakehouse'!O6:O95,'BOM 02-medallion-lakehouse'!C6:C95,"<>Recommended baseline") -> 26.624 | H9: =SUMIF('BOM 02-medallion-lakehouse'!C6:C95,"Recommended baseline",'BOM 02-medallion-lakehouse'!O6:O95) -> 330.434 | I9: =SUM('BOM 02-medallion-lakehouse'!V6:V95) -> 357.058 | J9: =SUM('BOM 02-medallion-lakehouse'!W6:W95) -> 357.058 | K9: =SUM('BOM 02-medallion-lakehouse'!X6:X95) -> 357.058 | L9: =COUNTIF('BOM 02-medallion-lakehouse'!V6:V95,"UNPRICED") -> 3 | M9: =COUNTIF('BOM 02-medallion-lakehouse'!W6:W95,"UNPRICED") -> 3 | N9: =COUNTIF('BOM 02-medallion-lakehouse'!X6:X95,"UNPRICED") -> 3
A10: BOM 03-real-time-intelligence | B10: ='BOM 03-real-time-intelligence'!B2 -> dev | C10: ='BOM 03-real-time-intelligence'!H2 -> 357.058 | D10: =C10*Assumptions!$B$8 -> 4284.696 | E10: ='BOM 03-real-time-intelligence'!K2 -> 3 | F10: ='BOM 03-real-time-intelligence'!N2 -> INCOMPLETE | G10: =SUMIFS('BOM 03-real-time-intelligence'!O6:O53,'BOM 03-real-time-intelligence'!C6:C53,"<>Recommended baseline") -> 26.624 | H10: =SUMIF('BOM 03-real-time-intelligence'!C6:C53,"Recommended baseline",'BOM 03-real-time-intelligence'!O6:O53) -> 330.434 | I10: =SUM('BOM 03-real-time-intelligence'!V6:V53) -> 357.058 | J10: =SUM('BOM 03-real-time-intelligence'!W6:W53) -> 357.058 | K10: =SUM('BOM 03-real-time-intelligence'!X6:X53) -> 357.058 | L10: =COUNTIF('BOM 03-real-time-intelligence'!V6:V53,"UNPRICED") -> 3 | M10: =COUNTIF('BOM 03-real-time-intelligence'!W6:W53,"UNPRICED") -> 3 | N10: =COUNTIF('BOM 03-real-time-intelligence'!X6:X53,"UNPRICED") -> 3
A11: BOM 04-data-science | B11: ='BOM 04-data-science'!B2 -> dev | C11: ='BOM 04-data-science'!H2 -> 357.058 | D11: =C11*Assumptions!$B$8 -> 4284.696 | E11: ='BOM 04-data-science'!K2 -> 3 | F11: ='BOM 04-data-science'!N2 -> INCOMPLETE | G11: =SUMIFS('BOM 04-data-science'!O6:O59,'BOM 04-data-science'!C6:C59,"<>Recommended baseline") -> 26.624 | H11: =SUMIF('BOM 04-data-science'!C6:C59,"Recommended baseline",'BOM 04-data-science'!O6:O59) -> 330.434 | I11: =SUM('BOM 04-data-science'!V6:V59) -> 357.058 | J11: =SUM('BOM 04-data-science'!W6:W59) -> 357.058 | K11: =SUM('BOM 04-data-science'!X6:X59) -> 357.058 | L11: =COUNTIF('BOM 04-data-science'!V6:V59,"UNPRICED") -> 3 | M11: =COUNTIF('BOM 04-data-science'!W6:W59,"UNPRICED") -> 3 | N11: =COUNTIF('BOM 04-data-science'!X6:X59,"UNPRICED") -> 3
A12: BOM 05-multi-environment | B12: ='BOM 05-multi-environment'!B2 -> dev | C12: ='BOM 05-multi-environment'!H2 -> 357.058 | D12: =C12*Assumptions!$B$8 -> 4284.696 | E12: ='BOM 05-multi-environment'!K2 -> 3 | F12: ='BOM 05-multi-environment'!N2 -> INCOMPLETE | G12: =SUMIFS('BOM 05-multi-environment'!O6:O80,'BOM 05-multi-environment'!C6:C80,"<>Recommended baseline") -> 26.624 | H12: =SUMIF('BOM 05-multi-environment'!C6:C80,"Recommended baseline",'BOM 05-multi-environment'!O6:O80) -> 330.434 | I12: =SUM('BOM 05-multi-environment'!V6:V80) -> 357.058 | J12: =SUM('BOM 05-multi-environment'!W6:W80) -> 357.058 | K12: =SUM('BOM 05-multi-environment'!X6:X80) -> 357.058 | L12: =COUNTIF('BOM 05-multi-environment'!V6:V80,"UNPRICED") -> 3 | M12: =COUNTIF('BOM 05-multi-environment'!W6:W80,"UNPRICED") -> 3 | N12: =COUNTIF('BOM 05-multi-environment'!X6:X80,"UNPRICED") -> 3
A13: BOM 06-shortcuts-and-connectio | B13: ='BOM 06-shortcuts-and-connectio'!B2 -> dev | C13: ='BOM 06-shortcuts-and-connectio'!H2 -> 357.058 | D13: =C13*Assumptions!$B$8 -> 4284.696 | E13: ='BOM 06-shortcuts-and-connectio'!K2 -> 3 | F13: ='BOM 06-shortcuts-and-connectio'!N2 -> INCOMPLETE | G13: =SUMIFS('BOM 06-shortcuts-and-connectio'!O6:O26,'BOM 06-shortcuts-and-connectio'!C6:C26,"<>Recommended baseline") -> 26.624 | H13: =SUMIF('BOM 06-shortcuts-and-connectio'!C6:C26,"Recommended baseline",'BOM 06-shortcuts-and-connectio'!O6:O26) -> 330.434 | I13: =SUM('BOM 06-shortcuts-and-connectio'!V6:V26) -> 357.058 | J13: =SUM('BOM 06-shortcuts-and-connectio'!W6:W26) -> 357.058 | K13: =SUM('BOM 06-shortcuts-and-connectio'!X6:X26) -> 357.058 | L13: =COUNTIF('BOM 06-shortcuts-and-connectio'!V6:V26,"UNPRICED") -> 3 | M13: =COUNTIF('BOM 06-shortcuts-and-connectio'!W6:W26,"UNPRICED") -> 3 | N13: =COUNTIF('BOM 06-shortcuts-and-connectio'!X6:X26,"UNPRICED") -> 3
A14: BOM 07-shortcut-transformation | B14: ='BOM 07-shortcut-transformation'!B2 -> dev | C14: ='BOM 07-shortcut-transformation'!H2 -> 357.058 | D14: =C14*Assumptions!$B$8 -> 4284.696 | E14: ='BOM 07-shortcut-transformation'!K2 -> 3 | F14: ='BOM 07-shortcut-transformation'!N2 -> INCOMPLETE | G14: =SUMIFS('BOM 07-shortcut-transformation'!O6:O26,'BOM 07-shortcut-transformation'!C6:C26,"<>Recommended baseline") -> 26.624 | H14: =SUMIF('BOM 07-shortcut-transformation'!C6:C26,"Recommended baseline",'BOM 07-shortcut-transformation'!O6:O26) -> 330.434 | I14: =SUM('BOM 07-shortcut-transformation'!V6:V26) -> 357.058 | J14: =SUM('BOM 07-shortcut-transformation'!W6:W26) -> 357.058 | K14: =SUM('BOM 07-shortcut-transformation'!X6:X26) -> 357.058 | L14: =COUNTIF('BOM 07-shortcut-transformation'!V6:V26,"UNPRICED") -> 3 | M14: =COUNTIF('BOM 07-shortcut-transformation'!W6:W26,"UNPRICED") -> 3 | N14: =COUNTIF('BOM 07-shortcut-transformation'!X6:X26,"UNPRICED") -> 3
A15: BOM 08-all-resource-types | B15: ='BOM 08-all-resource-types'!B2 -> dev | C15: ='BOM 08-all-resource-types'!H2 -> 357.058 | D15: =C15*Assumptions!$B$8 -> 4284.696 | E15: ='BOM 08-all-resource-types'!K2 -> 3 | F15: ='BOM 08-all-resource-types'!N2 -> INCOMPLETE | G15: =SUMIFS('BOM 08-all-resource-types'!O6:O135,'BOM 08-all-resource-types'!C6:C135,"<>Recommended baseline") -> 26.624 | H15: =SUMIF('BOM 08-all-resource-types'!C6:C135,"Recommended baseline",'BOM 08-all-resource-types'!O6:O135) -> 330.434 | I15: =SUM('BOM 08-all-resource-types'!V6:V135) -> 357.058 | J15: =SUM('BOM 08-all-resource-types'!W6:W135) -> 357.058 | K15: =SUM('BOM 08-all-resource-types'!X6:X135) -> 357.058 | L15: =COUNTIF('BOM 08-all-resource-types'!V6:V135,"UNPRICED") -> 3 | M15: =COUNTIF('BOM 08-all-resource-types'!W6:W135,"UNPRICED") -> 3 | N15: =COUNTIF('BOM 08-all-resource-types'!X6:X135,"UNPRICED") -> 3
A16: BOM 09-tenant-settings | B16: ='BOM 09-tenant-settings'!B2 -> prod | C16: ='BOM 09-tenant-settings'!H2 -> 330.434 | D16: =C16*Assumptions!$B$8 -> 3965.208 | E16: ='BOM 09-tenant-settings'!K2 -> 3 | F16: ='BOM 09-tenant-settings'!N2 -> INCOMPLETE | G16: =SUMIFS('BOM 09-tenant-settings'!O6:O26,'BOM 09-tenant-settings'!C6:C26,"<>Recommended baseline") -> 0 | H16: =SUMIF('BOM 09-tenant-settings'!C6:C26,"Recommended baseline",'BOM 09-tenant-settings'!O6:O26) -> 330.434 | I16: =SUM('BOM 09-tenant-settings'!V6:V26) -> 330.434 | J16: =SUM('BOM 09-tenant-settings'!W6:W26) -> 330.434 | K16: =SUM('BOM 09-tenant-settings'!X6:X26) -> 330.434 | L16: =COUNTIF('BOM 09-tenant-settings'!V6:V26,"UNPRICED") -> 3 | M16: =COUNTIF('BOM 09-tenant-settings'!W6:W26,"UNPRICED") -> 3 | N16: =COUNTIF('BOM 09-tenant-settings'!X6:X26,"UNPRICED") -> 3
A17: BOM 10-azure-and-entra | B17: ='BOM 10-azure-and-entra'!B2 -> dev | C17: ='BOM 10-azure-and-entra'!H2 -> 356.6932 | D17: =C17*Assumptions!$B$8 -> 4280.3184 | E17: ='BOM 10-azure-and-entra'!K2 -> 3 | F17: ='BOM 10-azure-and-entra'!N2 -> INCOMPLETE | G17: =SUMIFS('BOM 10-azure-and-entra'!O6:O27,'BOM 10-azure-and-entra'!C6:C27,"<>Recommended baseline") -> 48.7632 | H17: =SUMIF('BOM 10-azure-and-entra'!C6:C27,"Recommended baseline",'BOM 10-azure-and-entra'!O6:O27) -> 307.93 | I17: =SUM('BOM 10-azure-and-entra'!V6:V27) -> 356.6932 | J17: =SUM('BOM 10-azure-and-entra'!W6:W27) -> 356.6932 | K17: =SUM('BOM 10-azure-and-entra'!X6:X27) -> 356.6932 | L17: =COUNTIF('BOM 10-azure-and-entra'!V6:V27,"UNPRICED") -> 3 | M17: =COUNTIF('BOM 10-azure-and-entra'!W6:W27,"UNPRICED") -> 3 | N17: =COUNTIF('BOM 10-azure-and-entra'!X6:X27,"UNPRICED") -> 3
A18: BOM 11-azure-data-services | B18: ='BOM 11-azure-data-services'!B2 -> dev | C18: ='BOM 11-azure-data-services'!H2 -> 2423.1384 | D18: =C18*Assumptions!$B$8 -> 29077.661 | E18: ='BOM 11-azure-data-services'!K2 -> 16 | F18: ='BOM 11-azure-data-services'!N2 -> INCOMPLETE | G18: =SUMIFS('BOM 11-azure-data-services'!O6:O60,'BOM 11-azure-data-services'!C6:C60,"<>Recommended baseline") -> 2114.9084 | H18: =SUMIF('BOM 11-azure-data-services'!C6:C60,"Recommended baseline",'BOM 11-azure-data-services'!O6:O60) -> 308.23 | I18: =SUM('BOM 11-azure-data-services'!V6:V60) -> 2423.1384 | J18: =SUM('BOM 11-azure-data-services'!W6:W60) -> 2003.0252 | K18: =SUM('BOM 11-azure-data-services'!X6:X60) -> 1764.5807 | L18: =COUNTIF('BOM 11-azure-data-services'!V6:V60,"UNPRICED") -> 16 | M18: =COUNTIF('BOM 11-azure-data-services'!W6:W60,"UNPRICED") -> 16 | N18: =COUNTIF('BOM 11-azure-data-services'!X6:X60,"UNPRICED") -> 16
A19: BOM 12-azure-platform-services | B19: ='BOM 12-azure-platform-services'!B2 -> dev | C19: ='BOM 12-azure-platform-services'!H2 -> 1630.224 | D19: =C19*Assumptions!$B$8 -> 19562.688 | E19: ='BOM 12-azure-platform-services'!K2 -> 15 | F19: ='BOM 12-azure-platform-services'!N2 -> INCOMPLETE | G19: =SUMIFS('BOM 12-azure-platform-services'!O6:O61,'BOM 12-azure-platform-services'!C6:C61,"<>Recommended baseline") -> 1502.29 | H19: =SUMIF('BOM 12-azure-platform-services'!C6:C61,"Recommended baseline",'BOM 12-azure-platform-services'!O6:O61) -> 127.934 | I19: =SUM('BOM 12-azure-platform-services'!V6:V61) -> 1630.224 | J19: =SUM('BOM 12-azure-platform-services'!W6:W61) -> 1630.224 | K19: =SUM('BOM 12-azure-platform-services'!X6:X61) -> 1630.224 | L19: =COUNTIF('BOM 12-azure-platform-services'!V6:V61,"UNPRICED") -> 15 | M19: =COUNTIF('BOM 12-azure-platform-services'!W6:W61,"UNPRICED") -> 15 | N19: =COUNTIF('BOM 12-azure-platform-services'!X6:X61,"UNPRICED") -> 15
A20: BOM 13-realtime-governance | B20: ='BOM 13-realtime-governance'!B2 -> dev | C20: ='BOM 13-realtime-governance'!H2 -> 327.658 | D20: =C20*Assumptions!$B$8 -> 3931.896 | E20: ='BOM 13-realtime-governance'!K2 -> 3 | F20: ='BOM 13-realtime-governance'!N2 -> INCOMPLETE | G20: =SUMIFS('BOM 13-realtime-governance'!O6:O33,'BOM 13-realtime-governance'!C6:C33,"<>Recommended baseline") -> 195.524 | H20: =SUMIF('BOM 13-realtime-governance'!C6:C33,"Recommended baseline",'BOM 13-realtime-governance'!O6:O33) -> 132.134 | I20: =SUM('BOM 13-realtime-governance'!V6:V33) -> 327.658 | J20: =SUM('BOM 13-realtime-governance'!W6:W33) -> 327.658 | K20: =SUM('BOM 13-realtime-governance'!X6:X33) -> 327.658 | L20: =COUNTIF('BOM 13-realtime-governance'!V6:V33,"UNPRICED") -> 3 | M20: =COUNTIF('BOM 13-realtime-governance'!W6:W33,"UNPRICED") -> 3 | N20: =COUNTIF('BOM 13-realtime-governance'!X6:X33,"UNPRICED") -> 3
A21: BOM 14-streaming-lakehouse-gov | B21: ='BOM 14-streaming-lakehouse-gov'!B2 -> dev | C21: ='BOM 14-streaming-lakehouse-gov'!H2 -> 824.158 | D21: =C21*Assumptions!$B$8 -> 9889.896 | E21: ='BOM 14-streaming-lakehouse-gov'!K2 -> 4 | F21: ='BOM 14-streaming-lakehouse-gov'!N2 -> INCOMPLETE | G21: =SUMIFS('BOM 14-streaming-lakehouse-gov'!O6:O33,'BOM 14-streaming-lakehouse-gov'!C6:C33,"<>Recommended baseline") -> 692.024 | H21: =SUMIF('BOM 14-streaming-lakehouse-gov'!C6:C33,"Recommended baseline",'BOM 14-streaming-lakehouse-gov'!O6:O33) -> 132.134 | I21: =SUM('BOM 14-streaming-lakehouse-gov'!V6:V33) -> 824.158 | J21: =SUM('BOM 14-streaming-lakehouse-gov'!W6:W33) -> 716.838 | K21: =SUM('BOM 14-streaming-lakehouse-gov'!X6:X33) -> 654.56022 | L21: =COUNTIF('BOM 14-streaming-lakehouse-gov'!V6:V33,"UNPRICED") -> 4 | M21: =COUNTIF('BOM 14-streaming-lakehouse-gov'!W6:W33,"UNPRICED") -> 4 | N21: =COUNTIF('BOM 14-streaming-lakehouse-gov'!X6:X33,"UNPRICED") -> 4

Sheet Category Summary
A1: Known monthly costs by category | USD
A2: Costs exclude UNPRICED lines. Fabric starts unpriced; all subtotals remain partial until pricing gaps are resolved on the BOM.
A5: Scenario | B5: Target | C5: Fabric | D5: Infrastructure | E5: Security | F5: Storage | G5: AI | H5: AI / Compute | I5: Integration | J5: Database | K5: Monitoring | L5: Governance | M5: Review | N5: Unpriced lines
A6: Base udp.yml | B6: ='Base udp.yml'!B2 -> prod | C6: =SUMIF('Base udp.yml'!B6:B26,C$5,'Base udp.yml'!O6:O26) -> 0 | D6: =SUMIF('Base udp.yml'!B6:B26,D$5,'Base udp.yml'!O6:O26) -> 33.5 | E6: =SUMIF('Base udp.yml'!B6:B26,E$5,'Base udp.yml'!O6:O26) -> 129.3 | F6: =SUMIF('Base udp.yml'!B6:B26,F$5,'Base udp.yml'!O6:O26) -> 22.204 | G6: =SUMIF('Base udp.yml'!B6:B26,G$5,'Base udp.yml'!O6:O26) -> 76.43 | H6: =SUMIF('Base udp.yml'!B6:B26,H$5,'Base udp.yml'!O6:O26) -> 0 | I6: =SUMIF('Base udp.yml'!B6:B26,I$5,'Base udp.yml'!O6:O26) -> 0 | J6: =SUMIF('Base udp.yml'!B6:B26,J$5,'Base udp.yml'!O6:O26) -> 0 | K6: =SUMIF('Base udp.yml'!B6:B26,K$5,'Base udp.yml'!O6:O26) -> 69 | L6: =SUMIF('Base udp.yml'!B6:B26,L$5,'Base udp.yml'!O6:O26) -> 0 | M6: =SUMIF('Base udp.yml'!B6:B26,M$5,'Base udp.yml'!O6:O26) -> 0 | N6: ='Base udp.yml'!K2 -> 3
A7: BOM 00-default | B7: ='BOM 00-default'!B2 -> dev | C7: =SUMIF('BOM 00-default'!B6:B1473,C$5,'BOM 00-default'!O6:O1473) -> 8409.6 | D7: =SUMIF('BOM 00-default'!B6:B1473,D$5,'BOM 00-default'!O6:O1473) -> 959.83 | E7: =SUMIF('BOM 00-default'!B6:B1473,E$5,'BOM 00-default'!O6:O1473) -> 1058 | F7: =SUMIF('BOM 00-default'!B6:B1473,F$5,'BOM 00-default'!O6:O1473) -> 208.0688 | G7: =SUMIF('BOM 00-default'!B6:B1473,G$5,'BOM 00-default'!O6:O1473) -> 81.83 | H7: =SUMIF('BOM 00-default'!B6:B1473,H$5,'BOM 00-default'!O6:O1473) -> 620.5 | I7: =SUMIF('BOM 00-default'!B6:B1473,I$5,'BOM 00-default'!O6:O1473) -> 163.08 | J7: =SUMIF('BOM 00-default'!B6:B1473,J$5,'BOM 00-default'!O6:O1473) -> 708.12518 | K7: =SUMIF('BOM 00-default'!B6:B1473,K$5,'BOM 00-default'!O6:O1473) -> 72 | L7: =SUMIF('BOM 00-default'!B6:B1473,L$5,'BOM 00-default'!O6:O1473) -> 0 | M7: =SUMIF('BOM 00-default'!B6:B1473,M$5,'BOM 00-default'!O6:O1473) -> 0 | N7: ='BOM 00-default'!K2 -> 34
A8: BOM 01-minimal | B8: ='BOM 01-minimal'!B2 -> dev | C8: =SUMIF('BOM 01-minimal'!B6:B25,C$5,'BOM 01-minimal'!O6:O25) -> 8409.6 | D8: =SUMIF('BOM 01-minimal'!B6:B25,D$5,'BOM 01-minimal'!O6:O25) -> 33.5 | E8: =SUMIF('BOM 01-minimal'!B6:B25,E$5,'BOM 01-minimal'!O6:O25) -> 129.3 | F8: =SUMIF('BOM 01-minimal'!B6:B25,F$5,'BOM 01-minimal'!O6:O25) -> 48.828 | G8: =SUMIF('BOM 01-minimal'!B6:B25,G$5,'BOM 01-minimal'!O6:O25) -> 76.43 | H8: =SUMIF('BOM 01-minimal'!B6:B25,H$5,'BOM 01-minimal'!O6:O25) -> 0 | I8: =SUMIF('BOM 01-minimal'!B6:B25,I$5,'BOM 01-minimal'!O6:O25) -> 0 | J8: =SUMIF('BOM 01-minimal'!B6:B25,J$5,'BOM 01-minimal'!O6:O25) -> 0 | K8: =SUMIF('BOM 01-minimal'!B6:B25,K$5,'BOM 01-minimal'!O6:O25) -> 69 | L8: =SUMIF('BOM 01-minimal'!B6:B25,L$5,'BOM 01-minimal'!O6:O25) -> 0 | M8: =SUMIF('BOM 01-minimal'!B6:B25,M$5,'BOM 01-minimal'!O6:O25) -> 0 | N8: ='BOM 01-minimal'!K2 -> 2
A9: BOM 02-medallion-lakehouse | B9: ='BOM 02-medallion-lakehouse'!B2 -> dev | C9: =SUMIF('BOM 02-medallion-lakehouse'!B6:B95,C$5,'BOM 02-medallion-lakehouse'!O6:O95) -> 0 | D9: =SUMIF('BOM 02-medallion-lakehouse'!B6:B95,D$5,'BOM 02-medallion-lakehouse'!O6:O95) -> 33.5 | E9: =SUMIF('BOM 02-medallion-lakehouse'!B6:B95,E$5,'BOM 02-medallion-lakehouse'!O6:O95) -> 129.3 | F9: =SUMIF('BOM 02-medallion-lakehouse'!B6:B95,F$5,'BOM 02-medallion-lakehouse'!O6:O95) -> 48.828 | G9: =SUMIF('BOM 02-medallion-lakehouse'!B6:B95,G$5,'BOM 02-medallion-lakehouse'!O6:O95) -> 76.43 | H9: =SUMIF('BOM 02-medallion-lakehouse'!B6:B95,H$5,'BOM 02-medallion-lakehouse'!O6:O95) -> 0 | I9: =SUMIF('BOM 02-medallion-lakehouse'!B6:B95,I$5,'BOM 02-medallion-lakehouse'!O6:O95) -> 0 | J9: =SUMIF('BOM 02-medallion-lakehouse'!B6:B95,J$5,'BOM 02-medallion-lakehouse'!O6:O95) -> 0 | K9: =SUMIF('BOM 02-medallion-lakehouse'!B6:B95,K$5,'BOM 02-medallion-lakehouse'!O6:O95) -> 69 | L9: =SUMIF('BOM 02-medallion-lakehouse'!B6:B95,L$5,'BOM 02-medallion-lakehouse'!O6:O95) -> 0 | M9: =SUMIF('BOM 02-medallion-lakehouse'!B6:B95,M$5,'BOM 02-medallion-lakehouse'!O6:O95) -> 0 | N9: ='BOM 02-medallion-lakehouse'!K2 -> 3
A10: BOM 03-real-time-intelligence | B10: ='BOM 03-real-time-intelligence'!B2 -> dev | C10: =SUMIF('BOM 03-real-time-intelligence'!B6:B53,C$5,'BOM 03-real-time-intelligence'!O6:O53) -> 0 | D10: =SUMIF('BOM 03-real-time-intelligence'!B6:B53,D$5,'BOM 03-real-time-intelligence'!O6:O53) -> 33.5 | E10: =SUMIF('BOM 03-real-time-intelligence'!B6:B53,E$5,'BOM 03-real-time-intelligence'!O6:O53) -> 129.3 | F10: =SUMIF('BOM 03-real-time-intelligence'!B6:B53,F$5,'BOM 03-real-time-intelligence'!O6:O53) -> 48.828 | G10: =SUMIF('BOM 03-real-time-intelligence'!B6:B53,G$5,'BOM 03-real-time-intelligence'!O6:O53) -> 76.43 | H10: =SUMIF('BOM 03-real-time-intelligence'!B6:B53,H$5,'BOM 03-real-time-intelligence'!O6:O53) -> 0 | I10: =SUMIF('BOM 03-real-time-intelligence'!B6:B53,I$5,'BOM 03-real-time-intelligence'!O6:O53) -> 0 | J10: =SUMIF('BOM 03-real-time-intelligence'!B6:B53,J$5,'BOM 03-real-time-intelligence'!O6:O53) -> 0 | K10: =SUMIF('BOM 03-real-time-intelligence'!B6:B53,K$5,'BOM 03-real-time-intelligence'!O6:O53) -> 69 | L10: =SUMIF('BOM 03-real-time-intelligence'!B6:B53,L$5,'BOM 03-real-time-intelligence'!O6:O53) -> 0 | M10: =SUMIF('BOM 03-real-time-intelligence'!B6:B53,M$5,'BOM 03-real-time-intelligence'!O6:O53) -> 0 | N10: ='BOM 03-real-time-intelligence'!K2 -> 3
A11: BOM 04-data-science | B11: ='BOM 04-data-science'!B2 -> dev | C11: =SUMIF('BOM 04-data-science'!B6:B59,C$5,'BOM 04-data-science'!O6:O59) -> 0 | D11: =SUMIF('BOM 04-data-science'!B6:B59,D$5,'BOM 04-data-science'!O6:O59) -> 33.5 | E11: =SUMIF('BOM 04-data-science'!B6:B59,E$5,'BOM 04-data-science'!O6:O59) -> 129.3 | F11: =SUMIF('BOM 04-data-science'!B6:B59,F$5,'BOM 04-data-science'!O6:O59) -> 48.828 | G11: =SUMIF('BOM 04-data-science'!B6:B59,G$5,'BOM 04-data-science'!O6:O59) -> 76.43 | H11: =SUMIF('BOM 04-data-science'!B6:B59,H$5,'BOM 04-data-science'!O6:O59) -> 0 | I11: =SUMIF('BOM 04-data-science'!B6:B59,I$5,'BOM 04-data-science'!O6:O59) -> 0 | J11: =SUMIF('BOM 04-data-science'!B6:B59,J$5,'BOM 04-data-science'!O6:O59) -> 0 | K11: =SUMIF('BOM 04-data-science'!B6:B59,K$5,'BOM 04-data-science'!O6:O59) -> 69 | L11: =SUMIF('BOM 04-data-science'!B6:B59,L$5,'BOM 04-data-science'!O6:O59) -> 0 | M11: =SUMIF('BOM 04-data-science'!B6:B59,M$5,'BOM 04-data-science'!O6:O59) -> 0 | N11: ='BOM 04-data-science'!K2 -> 3
A12: BOM 05-multi-environment | B12: ='BOM 05-multi-environment'!B2 -> dev | C12: =SUMIF('BOM 05-multi-environment'!B6:B80,C$5,'BOM 05-multi-environment'!O6:O80) -> 0 | D12: =SUMIF('BOM 05-multi-environment'!B6:B80,D$5,'BOM 05-multi-environment'!O6:O80) -> 33.5 | E12: =SUMIF('BOM 05-multi-environment'!B6:B80,E$5,'BOM 05-multi-environment'!O6:O80) -> 129.3 | F12: =SUMIF('BOM 05-multi-environment'!B6:B80,F$5,'BOM 05-multi-environment'!O6:O80) -> 48.828 | G12: =SUMIF('BOM 05-multi-environment'!B6:B80,G$5,'BOM 05-multi-environment'!O6:O80) -> 76.43 | H12: =SUMIF('BOM 05-multi-environment'!B6:B80,H$5,'BOM 05-multi-environment'!O6:O80) -> 0 | I12: =SUMIF('BOM 05-multi-environment'!B6:B80,I$5,'BOM 05-multi-environment'!O6:O80) -> 0 | J12: =SUMIF('BOM 05-multi-environment'!B6:B80,J$5,'BOM 05-multi-environment'!O6:O80) -> 0 | K12: =SUMIF('BOM 05-multi-environment'!B6:B80,K$5,'BOM 05-multi-environment'!O6:O80) -> 69 | L12: =SUMIF('BOM 05-multi-environment'!B6:B80,L$5,'BOM 05-multi-environment'!O6:O80) -> 0 | M12: =SUMIF('BOM 05-multi-environment'!B6:B80,M$5,'BOM 05-multi-environment'!O6:O80) -> 0 | N12: ='BOM 05-multi-environment'!K2 -> 3
A13: BOM 06-shortcuts-and-connectio | B13: ='BOM 06-shortcuts-and-connectio'!B2 -> dev | C13: =SUMIF('BOM 06-shortcuts-and-connectio'!B6:B26,C$5,'BOM 06-shortcuts-and-connectio'!O6:O26) -> 0 | D13: =SUMIF('BOM 06-shortcuts-and-connectio'!B6:B26,D$5,'BOM 06-shortcuts-and-connectio'!O6:O26) -> 33.5 | E13: =SUMIF('BOM 06-shortcuts-and-connectio'!B6:B26,E$5,'BOM 06-shortcuts-and-connectio'!O6:O26) -> 129.3 | F13: =SUMIF('BOM 06-shortcuts-and-connectio'!B6:B26,F$5,'BOM 06-shortcuts-and-connectio'!O6:O26) -> 48.828 | G13: =SUMIF('BOM 06-shortcuts-and-connectio'!B6:B26,G$5,'BOM 06-shortcuts-and-connectio'!O6:O26) -> 76.43 | H13: =SUMIF('BOM 06-shortcuts-and-connectio'!B6:B26,H$5,'BOM 06-shortcuts-and-connectio'!O6:O26) -> 0 | I13: =SUMIF('BOM 06-shortcuts-and-connectio'!B6:B26,I$5,'BOM 06-shortcuts-and-connectio'!O6:O26) -> 0 | J13: =SUMIF('BOM 06-shortcuts-and-connectio'!B6:B26,J$5,'BOM 06-shortcuts-and-connectio'!O6:O26) -> 0 | K13: =SUMIF('BOM 06-shortcuts-and-connectio'!B6:B26,K$5,'BOM 06-shortcuts-and-connectio'!O6:O26) -> 69 | L13: =SUMIF('BOM 06-shortcuts-and-connectio'!B6:B26,L$5,'BOM 06-shortcuts-and-connectio'!O6:O26) -> 0 | M13: =SUMIF('BOM 06-shortcuts-and-connectio'!B6:B26,M$5,'BOM 06-shortcuts-and-connectio'!O6:O26) -> 0 | N13: ='BOM 06-shortcuts-and-connectio'!K2 -> 3
A14: BOM 07-shortcut-transformation | B14: ='BOM 07-shortcut-transformation'!B2 -> dev | C14: =SUMIF('BOM 07-shortcut-transformation'!B6:B26,C$5,'BOM 07-shortcut-transformation'!O6:O26) -> 0 | D14: =SUMIF('BOM 07-shortcut-transformation'!B6:B26,D$5,'BOM 07-shortcut-transformation'!O6:O26) -> 33.5 | E14: =SUMIF('BOM 07-shortcut-transformation'!B6:B26,E$5,'BOM 07-shortcut-transformation'!O6:O26) -> 129.3 | F14: =SUMIF('BOM 07-shortcut-transformation'!B6:B26,F$5,'BOM 07-shortcut-transformation'!O6:O26) -> 48.828 | G14: =SUMIF('BOM 07-shortcut-transformation'!B6:B26,G$5,'BOM 07-shortcut-transformation'!O6:O26) -> 76.43 | H14: =SUMIF('BOM 07-shortcut-transformation'!B6:B26,H$5,'BOM 07-shortcut-transformation'!O6:O26) -> 0 | I14: =SUMIF('BOM 07-shortcut-transformation'!B6:B26,I$5,'BOM 07-shortcut-transformation'!O6:O26) -> 0 | J14: =SUMIF('BOM 07-shortcut-transformation'!B6:B26,J$5,'BOM 07-shortcut-transformation'!O6:O26) -> 0 | K14: =SUMIF('BOM 07-shortcut-transformation'!B6:B26,K$5,'BOM 07-shortcut-transformation'!O6:O26) -> 69 | L14: =SUMIF('BOM 07-shortcut-transformation'!B6:B26,L$5,'BOM 07-shortcut-transformation'!O6:O26) -> 0 | M14: =SUMIF('BOM 07-shortcut-transformation'!B6:B26,M$5,'BOM 07-shortcut-transformation'!O6:O26) -> 0 | N14: ='BOM 07-shortcut-transformation'!K2 -> 3
A15: BOM 08-all-resource-types | B15: ='BOM 08-all-resource-types'!B2 -> dev | C15: =SUMIF('BOM 08-all-resource-types'!B6:B135,C$5,'BOM 08-all-resource-types'!O6:O135) -> 0 | D15: =SUMIF('BOM 08-all-resource-types'!B6:B135,D$5,'BOM 08-all-resource-types'!O6:O135) -> 33.5 | E15: =SUMIF('BOM 08-all-resource-types'!B6:B135,E$5,'BOM 08-all-resource-types'!O6:O135) -> 129.3 | F15: =SUMIF('BOM 08-all-resource-types'!B6:B135,F$5,'BOM 08-all-resource-types'!O6:O135) -> 48.828 | G15: =SUMIF('BOM 08-all-resource-types'!B6:B135,G$5,'BOM 08-all-resource-types'!O6:O135) -> 76.43 | H15: =SUMIF('BOM 08-all-resource-types'!B6:B135,H$5,'BOM 08-all-resource-types'!O6:O135) -> 0 | I15: =SUMIF('BOM 08-all-resource-types'!B6:B135,I$5,'BOM 08-all-resource-types'!O6:O135) -> 0 | J15: =SUMIF('BOM 08-all-resource-types'!B6:B135,J$5,'BOM 08-all-resource-types'!O6:O135) -> 0 | K15: =SUMIF('BOM 08-all-resource-types'!B6:B135,K$5,'BOM 08-all-resource-types'!O6:O135) -> 69 | L15: =SUMIF('BOM 08-all-resource-types'!B6:B135,L$5,'BOM 08-all-resource-types'!O6:O135) -> 0 | M15: =SUMIF('BOM 08-all-resource-types'!B6:B135,M$5,'BOM 08-all-resource-types'!O6:O135) -> 0 | N15: ='BOM 08-all-resource-types'!K2 -> 3
A16: BOM 09-tenant-settings | B16: ='BOM 09-tenant-settings'!B2 -> prod | C16: =SUMIF('BOM 09-tenant-settings'!B6:B26,C$5,'BOM 09-tenant-settings'!O6:O26) -> 0 | D16: =SUMIF('BOM 09-tenant-settings'!B6:B26,D$5,'BOM 09-tenant-settings'!O6:O26) -> 33.5 | E16: =SUMIF('BOM 09-tenant-settings'!B6:B26,E$5,'BOM 09-tenant-settings'!O6:O26) -> 129.3 | F16: =SUMIF('BOM 09-tenant-settings'!B6:B26,F$5,'BOM 09-tenant-settings'!O6:O26) -> 22.204 | G16: =SUMIF('BOM 09-tenant-settings'!B6:B26,G$5,'BOM 09-tenant-settings'!O6:O26) -> 76.43 | H16: =SUMIF('BOM 09-tenant-settings'!B6:B26,H$5,'BOM 09-tenant-settings'!O6:O26) -> 0 | I16: =SUMIF('BOM 09-tenant-settings'!B6:B26,I$5,'BOM 09-tenant-settings'!O6:O26) -> 0 | J16: =SUMIF('BOM 09-tenant-settings'!B6:B26,J$5,'BOM 09-tenant-settings'!O6:O26) -> 0 | K16: =SUMIF('BOM 09-tenant-settings'!B6:B26,K$5,'BOM 09-tenant-settings'!O6:O26) -> 69 | L16: =SUMIF('BOM 09-tenant-settings'!B6:B26,L$5,'BOM 09-tenant-settings'!O6:O26) -> 0 | M16: =SUMIF('BOM 09-tenant-settings'!B6:B26,M$5,'BOM 09-tenant-settings'!O6:O26) -> 0 | N16: ='BOM 09-tenant-settings'!K2 -> 3
A17: BOM 10-azure-and-entra | B17: ='BOM 10-azure-and-entra'!B2 -> dev | C17: =SUMIF('BOM 10-azure-and-entra'!B6:B27,C$5,'BOM 10-azure-and-entra'!O6:O27) -> 0 | D17: =SUMIF('BOM 10-azure-and-entra'!B6:B27,D$5,'BOM 10-azure-and-entra'!O6:O27) -> 33.5 | E17: =SUMIF('BOM 10-azure-and-entra'!B6:B27,E$5,'BOM 10-azure-and-entra'!O6:O27) -> 129.3 | F17: =SUMIF('BOM 10-azure-and-entra'!B6:B27,F$5,'BOM 10-azure-and-entra'!O6:O27) -> 48.4632 | G17: =SUMIF('BOM 10-azure-and-entra'!B6:B27,G$5,'BOM 10-azure-and-entra'!O6:O27) -> 76.43 | H17: =SUMIF('BOM 10-azure-and-entra'!B6:B27,H$5,'BOM 10-azure-and-entra'!O6:O27) -> 0 | I17: =SUMIF('BOM 10-azure-and-entra'!B6:B27,I$5,'BOM 10-azure-and-entra'!O6:O27) -> 0 | J17: =SUMIF('BOM 10-azure-and-entra'!B6:B27,J$5,'BOM 10-azure-and-entra'!O6:O27) -> 0 | K17: =SUMIF('BOM 10-azure-and-entra'!B6:B27,K$5,'BOM 10-azure-and-entra'!O6:O27) -> 69 | L17: =SUMIF('BOM 10-azure-and-entra'!B6:B27,L$5,'BOM 10-azure-and-entra'!O6:O27) -> 0 | M17: =SUMIF('BOM 10-azure-and-entra'!B6:B27,M$5,'BOM 10-azure-and-entra'!O6:O27) -> 0 | N17: ='BOM 10-azure-and-entra'!K2 -> 3
A18: BOM 11-azure-data-services | B18: ='BOM 11-azure-data-services'!B2 -> dev | C18: =SUMIF('BOM 11-azure-data-services'!B6:B60,C$5,'BOM 11-azure-data-services'!O6:O60) -> 0 | D18: =SUMIF('BOM 11-azure-data-services'!B6:B60,D$5,'BOM 11-azure-data-services'!O6:O60) -> 594.14 | E18: =SUMIF('BOM 11-azure-data-services'!B6:B60,E$5,'BOM 11-azure-data-services'!O6:O60) -> 129.3 | F18: =SUMIF('BOM 11-azure-data-services'!B6:B60,F$5,'BOM 11-azure-data-services'!O6:O60) -> 147.2432 | G18: =SUMIF('BOM 11-azure-data-services'!B6:B60,G$5,'BOM 11-azure-data-services'!O6:O60) -> 76.43 | H18: =SUMIF('BOM 11-azure-data-services'!B6:B60,H$5,'BOM 11-azure-data-services'!O6:O60) -> 620.5 | I18: =SUMIF('BOM 11-azure-data-services'!B6:B60,I$5,'BOM 11-azure-data-services'!O6:O60) -> 163.08 | J18: =SUMIF('BOM 11-azure-data-services'!B6:B60,J$5,'BOM 11-azure-data-services'!O6:O60) -> 623.44518 | K18: =SUMIF('BOM 11-azure-data-services'!B6:B60,K$5,'BOM 11-azure-data-services'!O6:O60) -> 69 | L18: =SUMIF('BOM 11-azure-data-services'!B6:B60,L$5,'BOM 11-azure-data-services'!O6:O60) -> 0 | M18: =SUMIF('BOM 11-azure-data-services'!B6:B60,M$5,'BOM 11-azure-data-services'!O6:O60) -> 0 | N18: ='BOM 11-azure-data-services'!K2 -> 16
A19: BOM 12-azure-platform-services | B19: ='BOM 12-azure-platform-services'!B2 -> dev | C19: =SUMIF('BOM 12-azure-platform-services'!B6:B61,C$5,'BOM 12-azure-platform-services'!O6:O61) -> 0 | D19: =SUMIF('BOM 12-azure-platform-services'!B6:B61,D$5,'BOM 12-azure-platform-services'!O6:O61) -> 399.19 | E19: =SUMIF('BOM 12-azure-platform-services'!B6:B61,E$5,'BOM 12-azure-platform-services'!O6:O61) -> 1058 | F19: =SUMIF('BOM 12-azure-platform-services'!B6:B61,F$5,'BOM 12-azure-platform-services'!O6:O61) -> 22.204 | G19: =SUMIF('BOM 12-azure-platform-services'!B6:B61,G$5,'BOM 12-azure-platform-services'!O6:O61) -> 81.83 | H19: =SUMIF('BOM 12-azure-platform-services'!B6:B61,H$5,'BOM 12-azure-platform-services'!O6:O61) -> 0 | I19: =SUMIF('BOM 12-azure-platform-services'!B6:B61,I$5,'BOM 12-azure-platform-services'!O6:O61) -> 0 | J19: =SUMIF('BOM 12-azure-platform-services'!B6:B61,J$5,'BOM 12-azure-platform-services'!O6:O61) -> 0 | K19: =SUMIF('BOM 12-azure-platform-services'!B6:B61,K$5,'BOM 12-azure-platform-services'!O6:O61) -> 69 | L19: =SUMIF('BOM 12-azure-platform-services'!B6:B61,L$5,'BOM 12-azure-platform-services'!O6:O61) -> 0 | M19: =SUMIF('BOM 12-azure-platform-services'!B6:B61,M$5,'BOM 12-azure-platform-services'!O6:O61) -> 0 | N19: ='BOM 12-azure-platform-services'!K2 -> 15
A20: BOM 13-realtime-governance | B20: ='BOM 13-realtime-governance'!B2 -> dev | C20: =SUMIF('BOM 13-realtime-governance'!B6:B33,C$5,'BOM 13-realtime-governance'!O6:O33) -> 0 | D20: =SUMIF('BOM 13-realtime-governance'!B6:B33,D$5,'BOM 13-realtime-governance'!O6:O33) -> 33.5 | E20: =SUMIF('BOM 13-realtime-governance'!B6:B33,E$5,'BOM 13-realtime-governance'!O6:O33) -> 143.9 | F20: =SUMIF('BOM 13-realtime-governance'!B6:B33,F$5,'BOM 13-realtime-governance'!O6:O33) -> 48.828 | G20: =SUMIF('BOM 13-realtime-governance'!B6:B33,G$5,'BOM 13-realtime-governance'!O6:O33) -> 76.43 | H20: =SUMIF('BOM 13-realtime-governance'!B6:B33,H$5,'BOM 13-realtime-governance'!O6:O33) -> 0 | I20: =SUMIF('BOM 13-realtime-governance'!B6:B33,I$5,'BOM 13-realtime-governance'!O6:O33) -> 25 | J20: =SUMIF('BOM 13-realtime-governance'!B6:B33,J$5,'BOM 13-realtime-governance'!O6:O33) -> 0 | K20: =SUMIF('BOM 13-realtime-governance'!B6:B33,K$5,'BOM 13-realtime-governance'!O6:O33) -> 0 | L20: =SUMIF('BOM 13-realtime-governance'!B6:B33,L$5,'BOM 13-realtime-governance'!O6:O33) -> 0 | M20: =SUMIF('BOM 13-realtime-governance'!B6:B33,M$5,'BOM 13-realtime-governance'!O6:O33) -> 0 | N20: ='BOM 13-realtime-governance'!K2 -> 3
A21: BOM 14-streaming-lakehouse-gov | B21: ='BOM 14-streaming-lakehouse-gov'!B2 -> dev | C21: =SUMIF('BOM 14-streaming-lakehouse-gov'!B6:B33,C$5,'BOM 14-streaming-lakehouse-gov'!O6:O33) -> 0 | D21: =SUMIF('BOM 14-streaming-lakehouse-gov'!B6:B33,D$5,'BOM 14-streaming-lakehouse-gov'!O6:O33) -> 313.82 | E21: =SUMIF('BOM 14-streaming-lakehouse-gov'!B6:B33,E$5,'BOM 14-streaming-lakehouse-gov'!O6:O33) -> 143.9 | F21: =SUMIF('BOM 14-streaming-lakehouse-gov'!B6:B33,F$5,'BOM 14-streaming-lakehouse-gov'!O6:O33) -> 48.828 | G21: =SUMIF('BOM 14-streaming-lakehouse-gov'!B6:B33,G$5,'BOM 14-streaming-lakehouse-gov'!O6:O33) -> 76.43 | H21: =SUMIF('BOM 14-streaming-lakehouse-gov'!B6:B33,H$5,'BOM 14-streaming-lakehouse-gov'!O6:O33) -> 219 | I21: =SUMIF('BOM 14-streaming-lakehouse-gov'!B6:B33,I$5,'BOM 14-streaming-lakehouse-gov'!O6:O33) -> 22.18 | J21: =SUMIF('BOM 14-streaming-lakehouse-gov'!B6:B33,J$5,'BOM 14-streaming-lakehouse-gov'!O6:O33) -> 0 | K21: =SUMIF('BOM 14-streaming-lakehouse-gov'!B6:B33,K$5,'BOM 14-streaming-lakehouse-gov'!O6:O33) -> 0 | L21: =SUMIF('BOM 14-streaming-lakehouse-gov'!B6:B33,L$5,'BOM 14-streaming-lakehouse-gov'!O6:O33) -> 0 | M21: =SUMIF('BOM 14-streaming-lakehouse-gov'!B6:B33,M$5,'BOM 14-streaming-lakehouse-gov'!O6:O33) -> 0 | N21: ='BOM 14-streaming-lakehouse-gov'!K2 -> 4

Sheet Assumptions
A1: Model assumptions | East US | USD
A3: Assumption | B3: Value | C3: Units / interpretation | D3: Source / caveat
A4: Currency | B4: USD | C4: All costs in USD | D4: User baseline; no currency conversion
A5: Active hours per month | B5: 730 | C5: Hours for continuously running PAYG compute | D5: Editable; reservation payments do not pause
A6: Days per modeled month | B6: =B5/24 -> 30.416667 | C6: Hours divided by 24 | D6: Used for daily meters; 730-hour modeling convention
A7: Default purchase plan | B7: PAYG | C7: PAYG / 1Y / 3Y | D7: Applies only to reservation-eligible SKUs
A8: Months in 1-year term | B8: 12 | C8: Months | D8: Reservation normalization
A9: Months in 3-year term | B9: 36 | C9: Months | D9: Reservation normalization
A10: Enable recommended baseline | B10: 1 | C10: 1 = enabled; 0 = YAML/dependency model only | D10: User requested enabled production planning baseline
A11: OneLake pooled storage | B11: 1024 | C11: GB-month per selected workspace | D11: Assumption; not multiplied by number of lakehouses
A12: Monitoring log ingestion | B12: 30 | C12: GB/month | D12: Gross billable usage; free allowances not deducted
A13: Azure OpenAI input | B13: 10 | C13: Million tokens/month | D13: GPT-4o-mini global deployment planning assumption
A14: Azure OpenAI output | B14: 2 | C14: Million tokens/month | D14: Output tokens billed separately
A15: ADLS / Blob capacity | B15: 1024 | C15: GB-month per account | D15: Assumption where YAML gives no volume
A16: Outbound network usage | B16: 100 | C16: Billable GB/month after free allowances | D16: Assumption; first paid band, no graduated-tier calculation
A17: Private endpoints | B17: 3 | C17: Endpoints | D17: Starter baseline: storage, Key Vault, AI; validate service support
A18: Private DNS zones | B18: 3 | C18: Zones | D18: Starter baseline; reuse existing declared zones
A19: Protected storage accounts | B19: 1 | C19: Accounts | D19: Defender for Storage baseline
... A24: Days per year | B24: 365 | C24: Days | D24: Reference only; no reservation discount is assumed

Sheet SKU Catalog
A1: SKU-driven rate catalog | normalized monthly rates
A3: Lookup key | B3: Capability | C3: Selectable SKU | D3: Category | E3: Size / usage unit | F3: Billing basis | G3: PAYG raw unit USD | H3: 1Y term USD | I3: 3Y term USD | J3: Reservation eligible | K3: PAYG monthly USD/unit | L3: 1Y monthly USD/unit | M3: 3Y monthly USD/unit | N3: Evidence / caveat
A4: Covered|Included / no separate meter | B4: Covered | C4: Included / no separate meter | D4: Fabric | E4: resource | F4: Usage | G4: 0 | H4: 0 | I4: 0 | J4: 0 | K4: =IF(ISNUMBER(G4),G4,"UNPRICED") -> 0 | L4: =IF(J4=0,K4,IF(ISNUMBER(H4),H4/Assumptions!$B$8,"UNPRICED")) -> 0 | M4: =IF(J4=0,K4,IF(ISNUMBER(I4),I4/Assumptions!$B$9,"UNPRICED")) -> 0 | N4: Fabric compute is covered by the capacity line, not free compute. Storage is pooled separately.
A5: Control plane|No direct provisioning charge | B5: Control plane | C5: No direct provisioning charge | D5: Governance | E5: resource | F5: Usage | G5: 0 | H5: 0 | I5: 0 | J5: 0 | K5: =IF(ISNUMBER(G5),G5,"UNPRICED") -> 0 | L5: =IF(J5=0,K5,IF(ISNUMBER(H5),H5/Assumptions!$B$8,"UNPRICED")) -> 0 | M5: =IF(J5=0,K5,IF(ISNUMBER(I5),I5/Assumptions!$B$9,"UNPRICED")) -> 0 | N5: No direct resource provisioning charge. Connected services, paid licenses, traffic, processing and exported logs are separate.
A6: Review|REVIEW REQUIRED | B6: Review | C6: REVIEW REQUIRED | D6: Review | E6: quoted unit | F6: Usage | G6: UNPRICED | H6: UNPRICED | I6: UNPRICED | J6: 0 | K6: =IF(ISNUMBER(G6),G6,"UNPRICED") -> UNPRICED | L6: =IF(J6=0,K6,IF(ISNUMBER(H6),H6/Assumptions!$B$8,"UNPRICED")) -> UNPRICED | M6: =IF(J6=0,K6,IF(ISNUMBER(I6),I6/Assumptions!$B$9,"UNPRICED")) -> UNPRICED | N6: Missing service/SKU/sizing or retired service. Enter a justified manual rate; do not interpret as zero.
A7: Fabric capacity|SELECT SKU | B7: Fabric capacity | C7: SELECT SKU | D7: Fabric | E7: capacity | F7: Hourly | G7: UNPRICED | H7: UNPRICED | I7: UNPRICED | J7: 1 | K7: =IF(ISNUMBER(G7),G7*Assumptions!$B$5,"UNPRICED") -> UNPRICED | L7: =IF(J7=0,K7,IF(ISNUMBER(H7),H7/Assumptions!$B$8,"UNPRICED")) -> UNPRICED | M7: =IF(J7=0,K7,IF(ISNUMBER(I7),I7/Assumptions!$B$9,"UNPRICED")) -> UNPRICED | N7: YAML specifies capacity ID, not F SKU. Select F2-F8192; not a sizing recommendation.
A8: Fabric capacity|F2 | B8: Fabric capacity | C8: F2 | D8: Fabric | E8: capacity | F8: Hourly | G8: ='Price Evidence'!I4*2 -> 0.36 | H8: ='Price Evidence'!I5*2 -> 1876 | I8: ='Price Evidence'!I6*2 -> 5628 | J8: 1 | K8: =IF(ISNUMBER(G8),G8*Assumptions!$B$5,"UNPRICED") -> 262.8 | L8: =IF(J8=0,K8,IF(ISNUMBER(H8),H8/Assumptions!$B$8,"UNPRICED")) -> 156.33333 | M8: =IF(J8=0,K8,IF(ISNUMBER(I8),I8/Assumptions!$B$9,"UNPRICED")) -> 156.33333 | N8: Standard CU-hour pool rate x F-SKU CUs. Reservations are full-term CU commitments; all workloads share the pool.
A9: Fabric capacity|F4 | B9: Fabric capacity | C9: F4 | D9: Fabric | E9: capacity | F9: Hourly | G9: ='Price Evidence'!I4*4 -> 0.72 | H9: ='Price Evidence'!I5*4 -> 3752 | I9: ='Price Evidence'!I6*4 -> 11256 | J9: 1 | K9: =IF(ISNUMBER(G9),G9*Assumptions!$B$5,"UNPRICED") -> 525.6 | L9: =IF(J9=0,K9,IF(ISNUMBER(H9),H9/Assumptions!$B$8,"UNPRICED")) -> 312.66667 | M9: =IF(J9=0,K9,IF(ISNUMBER(I9),I9/Assumptions!$B$9,"UNPRICED")) -> 312.66667 | N9: Standard CU-hour pool rate x F-SKU CUs. Reservations are full-term CU commitments; all workloads share the pool.
A10: Fabric capacity|F8 | B10: Fabric capacity | C10: F8 | D10: Fabric | E10: capacity | F10: Hourly | G10: ='Price Evidence'!I4*8 -> 1.44 | H10: ='Price Evidence'!I5*8 -> 7504 | I10: ='Price Evidence'!I6*8 -> 22512 | J10: 1 | K10: =IF(ISNUMBER(G10),G10*Assumptions!$B$5,"UNPRICED") -> 1051.2 | L10: =IF(J10=0,K10,IF(ISNUMBER(H10),H10/Assumptions!$B$8,"UNPRICED")) -> 625.33333 | M10: =IF(J10=0,K10,IF(ISNUMBER(I10),I10/Assumptions!$B$9,"UNPRICED")) -> 625.33333 | N10: Standard CU-hour pool rate x F-SKU CUs. Reservations are full-term CU commitments; all workloads share the pool.
A11: Fabric capacity|F16 | B11: Fabric capacity | C11: F16 | D11: Fabric | E11: capacity | F11: Hourly | G11: ='Price Evidence'!I4*16 -> 2.88 | H11: ='Price Evidence'!I5*16 -> 15008 | I11: ='Price Evidence'!I6*16 -> 45024 | J11: 1 | K11: =IF(ISNUMBER(G11),G11*Assumptions!$B$5,"UNPRICED") -> 2102.4 | L11: =IF(J11=0,K11,IF(ISNUMBER(H11),H11/Assumptions!$B$8,"UNPRICED")) -> 1250.6667 | M11: =IF(J11=0,K11,IF(ISNUMBER(I11),I11/Assumptions!$B$9,"UNPRICED")) -> 1250.6667 | N11: Standard CU-hour pool rate x F-SKU CUs. Reservations are full-term CU commitments; all workloads share the pool.
A12: Fabric capacity|F32 | B12: Fabric capacity | C12: F32 | D12: Fabric | E12: capacity | F12: Hourly | G12: ='Price Evidence'!I4*32 -> 5.76 | H12: ='Price Evidence'!I5*32 -> 30016 | I12: ='Price Evidence'!I6*32 -> 90048 | J12: 1 | K12: =IF(ISNUMBER(G12),G12*Assumptions!$B$5,"UNPRICED") -> 4204.8 | L12: =IF(J12=0,K12,IF(ISNUMBER(H12),H12/Assumptions!$B$8,"UNPRICED")) -> 2501.3333 | M12: =IF(J12=0,K12,IF(ISNUMBER(I12),I12/Assumptions!$B$9,"UNPRICED")) -> 2501.3333 | N12: Standard CU-hour pool rate x F-SKU CUs. Reservations are full-term CU commitments; all workloads share the pool.
A13: Fabric capacity|F64 | B13: Fabric capacity | C13: F64 | D13: Fabric | E13: capacity | F13: Hourly | G13: ='Price Evidence'!I4*64 -> 11.52 | H13: ='Price Evidence'!I5*64 -> 60032 | I13: ='Price Evidence'!I6*64 -> 180096 | J13: 1 | K13: =IF(ISNUMBER(G13),G13*Assumptions!$B$5,"UNPRICED") -> 8409.6 | L13: =IF(J13=0,K13,IF(ISNUMBER(H13),H13/Assumptions!$B$8,"UNPRICED")) -> 5002.6667 | M13: =IF(J13=0,K13,IF(ISNUMBER(I13),I13/Assumptions!$B$9,"UNPRICED")) -> 5002.6667 | N13: Standard CU-hour pool rate x F-SKU CUs. Reservations are full-term CU commitments; all workloads share the pool.
A14: Fabric capacity|F128 | B14: Fabric capacity | C14: F128 | D14: Fabric | E14: capacity | F14: Hourly | G14: ='Price Evidence'!I4*128 -> 23.04 | H14: ='Price Evidence'!I5*128 -> 120064 | I14: ='Price Evidence'!I6*128 -> 360192 | J14: 1 | K14: =IF(ISNUMBER(G14),G14*Assumptions!$B$5,"UNPRICED") -> 16819.2 | L14: =IF(J14=0,K14,IF(ISNUMBER(H14),H14/Assumptions!$B$8,"UNPRICED")) -> 10005.333 | M14: =IF(J14=0,K14,IF(ISNUMBER(I14),I14/Assumptions!$B$9,"UNPRICED")) -> 10005.333 | N14: Standard CU-hour pool rate x F-SKU CUs. Reservations are full-term CU commitments; all workloads share the pool.
A15: Fabric capacity|F256 | B15: Fabric capacity | C15: F256 | D15: Fabric | E15: capacity | F15: Hourly | G15: ='Price Evidence'!I4*256 -> 46.08 | H15: ='Price Evidence'!I5*256 -> 240128 | I15: ='Price Evidence'!I6*256 -> 720384 | J15: 1 | K15: =IF(ISNUMBER(G15),G15*Assumptions!$B$5,"UNPRICED") -> 33638.4 | L15: =IF(J15=0,K15,IF(ISNUMBER(H15),H15/Assumptions!$B$8,"UNPRICED")) -> 20010.667 | M15: =IF(J15=0,K15,IF(ISNUMBER(I15),I15/Assumptions!$B$9,"UNPRICED")) -> 20010.667 | N15: Standard CU-hour pool rate x F-SKU CUs. Reservations are full-term CU commitments; all workloads share the pool.
A16: Fabric capacity|F512 | B16: Fabric capacity | C16: F512 | D16: Fabric | E16: capacity | F16: Hourly | G16: ='Price Evidence'!I4*512 -> 92.16 | H16: ='Price Evidence'!I5*512 -> 480256 | I16: ='Price Evidence'!I6*512 -> 1440768 | J16: 1 | K16: =IF(ISNUMBER(G16),G16*Assumptions!$B$5,"UNPRICED") -> 67276.8 | L16: =IF(J16=0,K16,IF(ISNUMBER(H16),H16/Assumptions!$B$8,"UNPRICED")) -> 40021.333 | M16: =IF(J16=0,K16,IF(ISNUMBER(I16),I16/Assumptions!$B$9,"UNPRICED")) -> 40021.333 | N16: Standard CU-hour pool rate x F-SKU CUs. Reservations are full-term CU commitments; all workloads share the pool.
A17: Fabric capacity|F1024 | B17: Fabric capacity | C17: F1024 | D17: Fabric | E17: capacity | F17: Hourly | G17: ='Price Evidence'!I4*1024 -> 184.32 | H17: ='Price Evidence'!I5*1024 -> 960512 | I17: ='Price Evidence'!I6*1024 -> 2881536 | J17: 1 | K17: =IF(ISNUMBER(G17),G17*Assumptions!$B$5,"UNPRICED") -> 134553.6 | L17: =IF(J17=0,K17,IF(ISNUMBER(H17),H17/Assumptions!$B$8,"UNPRICED")) -> 80042.667 | M17: =IF(J17=0,K17,IF(ISNUMBER(I17),I17/Assumptions!$B$9,"UNPRICED")) -> 80042.667 | N17: Standard CU-hour pool rate x F-SKU CUs. Reservations are full-term CU commitments; all workloads share the pool.
A18: Fabric capacity|F2048 | B18: Fabric capacity | C18: F2048 | D18: Fabric | E18: capacity | F18: Hourly | G18: ='Price Evidence'!I4*2048 -> 368.64 | H18: ='Price Evidence'!I5*2048 -> 1921024 | I18: ='Price Evidence'!I6*2048 -> 5763072 | J18: 1 | K18: =IF(ISNUMBER(G18),G18*Assumptions!$B$5,"UNPRICED") -> 269107.2 | L18: =IF(J18=0,K18,IF(ISNUMBER(H18),H18/Assumptions!$B$8,"UNPRICED")) -> 160085.33 | M18: =IF(J18=0,K18,IF(ISNUMBER(I18),I18/Assumptions!$B$9,"UNPRICED")) -> 160085.33 | N18: Standard CU-hour pool rate x F-SKU CUs. Reservations are full-term CU commitments; all workloads share the pool.
A19: Fabric capacity|F4096 | B19: Fabric capacity | C19: F4096 | D19: Fabric | E19: capacity | F19: Hourly | G19: ='Price Evidence'!I4*4096 -> 737.28 | H19: ='Price Evidence'!I5*4096 -> 3842048 | I19: ='Price Evidence'!I6*4096 -> 11526144 | J19: 1 | K19: =IF(ISNUMBER(G19),G19*Assumptions!$B$5,"UNPRICED") -> 538214.4 | L19: =IF(J19=0,K19,IF(ISNUMBER(H19),H19/Assumptions!$B$8,"UNPRICED")) -> 320170.67 | M19: =IF(J19=0,K19,IF(ISNUMBER(I19),I19/Assumptions!$B$9,"UNPRICED")) -> 320170.67 | N19: Standard CU-hour pool rate x F-SKU CUs. Reservations are full-term CU commitments; all workloads share the pool.
A20: Fabric capacity|F8192 | B20: Fabric capacity | C20: F8192 | D20: Fabric | E20: capacity | F20: Hourly | G20: ='Price Evidence'!I4*8192 -> 1474.56 | H20: ='Price Evidence'!I5*8192 -> 7684096 | I20: ='Price Evidence'!I6*8192 -> 23052288 | J20: 1 | K20: =IF(ISNUMBER(G20),G20*Assumptions!$B$5,"UNPRICED") -> 1076428.8 | L20: =IF(J20=0,K20,IF(ISNUMBER(H20),H20/Assumptions!$B$8,"UNPRICED")) -> 640341.33 | M20: =IF(J20=0,K20,IF(ISNUMBER(I20),I20/Assumptions!$B$9,"UNPRICED")) -> 640341.33 | N20: Standard CU-hour pool rate x F-SKU CUs. Reservations are full-term CU commitments; all workloads share the pool.
A21: OneLake storage|Hot | B21: OneLake storage | C21: Hot | D21: Storage | E21: GB-month | F21: Usage | G21: ='Price Evidence'!I7 -> 0.026 | H21: UNPRICED | I21: UNPRICED | J21: 0 | K21: =IF(ISNUMBER(G21),G21,"UNPRICED") -> 0.026 | L21: =IF(J21=0,K21,IF(ISNUMBER(H21),H21/Assumptions!$B$8,"UNPRICED")) -> 0.026 | M21: =IF(J21=0,K21,IF(ISNUMBER(I21),I21/Assumptions!$B$9,"UNPRICED")) -> 0.026 | N21: Pooled physical storage only; no shortcut source duplication; no mirroring allowance deduction.
A22: OneLake storage|Cool | B22: OneLake storage | C22: Cool | D22: Storage | E22: GB-month | F22: Usage | G22: ='Price Evidence'!I8 -> 0.019 | H22: UNPRICED | I22: UNPRICED | J22: 0 | K22: =IF(ISNUMBER(G22),G22,"UNPRICED") -> 0.019 | L22: =IF(J22=0,K22,IF(ISNUMBER(H22),H22/Assumptions!$B$8,"UNPRICED")) -> 0.019 | M22: =IF(J22=0,K22,IF(ISNUMBER(I22),I22/Assumptions!$B$9,"UNPRICED")) -> 0.019 | N22: Pooled physical storage only; no shortcut source duplication; no mirroring allowance deduction.
A23: OneLake storage|Cold | B23: OneLake storage | C23: Cold | D23: Storage | E23: GB-month | F23: Usage | G23: ='Price Evidence'!I9 -> 0.004 | H23: UNPRICED | I23: UNPRICED | J23: 0 | K23: =IF(ISNUMBER(G23),G23,"UNPRICED") -> 0.004 | L23: =IF(J23=0,K23,IF(ISNUMBER(H23),H23/Assumptions!$B$8,"UNPRICED")) -> 0.004 | M23: =IF(J23=0,K23,IF(ISNUMBER(I23),I23/Assumptions!$B$9,"UNPRICED")) -> 0.004 | N23: Pooled physical storage only; no shortcut source duplication; no mirroring allowance deduction.
A24: Blob storage|Hot LRS | B24: Blob storage | C24: Hot LRS | D24: Storage | E24: GB-month | F24: Usage | G24: ='Price Evidence'!I10 -> 0.0208 | H24: UNPRICED | I24: UNPRICED | J24: 0 | K24: =IF(ISNUMBER(G24),G24,"UNPRICED") -> 0.0208 | L24: =IF(J24=0,K24,IF(ISNUMBER(H24),H24/Assumptions!$B$8,"UNPRICED")) -> 0.0208 | M24: =IF(J24=0,K24,IF(ISNUMBER(I24),I24/Assumptions!$B$9,"UNPRICED")) -> 0.0208 | N24: First storage band; replication included in selected redundancy; retrieval and transaction meters are separate.
A25: Blob storage|Hot GRS | B25: Blob storage | C25: Hot GRS | D25: Storage | E25: GB-month | F25: Usage | G25: ='Price Evidence'!I11 -> 0.0458 | H25: UNPRICED | I25: UNPRICED | J25: 0 | K25: =IF(ISNUMBER(G25),G25,"UNPRICED") -> 0.0458 | L25: =IF(J25=0,K25,IF(ISNUMBER(H25),H25/Assumptions!$B$8,"UNPRICED")) -> 0.0458 | M25: =IF(J25=0,K25,IF(ISNUMBER(I25),I25/Assumptions!$B$9,"UNPRICED")) -> 0.0458 | N25: First storage band; replication included in selected redundancy; retrieval and transaction meters are separate.
A26: Blob storage|Hot ZRS | B26: Blob storage | C26: Hot ZRS | D26: Storage | E26: GB-month | F26: Usage | G26: ='Price Evidence'!I12 -> 0.026 | H26: UNPRICED | I26: UNPRICED | J26: 0 | K26: =IF(ISNUMBER(G26),G26,"UNPRICED") -> 0.026 | L26: =IF(J26=0,K26,IF(ISNUMBER(H26),H26/Assumptions!$B$8,"UNPRICED")) -> 0.026 | M26: =IF(J26=0,K26,IF(ISNUMBER(I26),I26/Assumptions!$B$9,"UNPRICED")) -> 0.026 | N26: First storage band; replication included in selected redundancy; retrieval and transaction meters are separate.
A27: Blob storage|Hot RA-GRS | B27: Blob storage | C27: Hot RA-GRS | D27: Storage | E27: GB-month | F27: Usage | G27: ='Price Evidence'!I13 -> 0.0589 | H27: UNPRICED | I27: UNPRICED | J27: 0 | K27: =IF(ISNUMBER(G27),G27,"UNPRICED") -> 0.0589 | L27: =IF(J27=0,K27,IF(ISNUMBER(H27),H27/Assumptions!$B$8,"UNPRICED")) -> 0.0589 | M27: =IF(J27=0,K27,IF(ISNUMBER(I27),I27/Assumptions!$B$9,"UNPRICED")) -> 0.0589 | N27: First storage band; replication included in selected redundancy; retrieval and transaction meters are separate.
A28: Blob storage|Cool LRS | B28: Blob storage | C28: Cool LRS | D28: Storage | E28: GB-month | F28: Usage | G28: ='Price Evidence'!I14 -> 0.0152 | H28: UNPRICED | I28: UNPRICED | J28: 0 | K28: =IF(ISNUMBER(G28),G28,"UNPRICED") -> 0.0152 | L28: =IF(J28=0,K28,IF(ISNUMBER(H28),H28/Assumptions!$B$8,"UNPRICED")) -> 0.0152 | M28: =IF(J28=0,K28,IF(ISNUMBER(I28),I28/Assumptions!$B$9,"UNPRICED")) -> 0.0152 | N28: First storage band; replication included in selected redundancy; retrieval and transaction meters are separate.
A29: Blob storage|Cool GRS | B29: Blob storage | C29: Cool GRS | D29: Storage | E29: GB-month | F29: Usage | G29: ='Price Evidence'!I15 -> 0.0334 | H29: UNPRICED | I29: UNPRICED | J29: 0 | K29: =IF(ISNUMBER(G29),G29,"UNPRICED") -> 0.0334 | L29: =IF(J29=0,K29,IF(ISNUMBER(H29),H29/Assumptions!$B$8,"UNPRICED")) -> 0.0334 | M29: =IF(J29=0,K29,IF(ISNUMBER(I29),I29/Assumptions!$B$9,"UNPRICED")) -> 0.0334 | N29: First storage band; replication included in selected redundancy; retrieval and transaction meters are separate.
A30: Blob storage|Cool ZRS | B30: Blob storage | C30: Cool ZRS | D30: Storage | E30: GB-month | F30: Usage | G30: ='Price Evidence'!I16 -> 0.019 | H30: UNPRICED | I30: UNPRICED | J30: 0 | K30: =IF(ISNUMBER(G30),G30,"UNPRICED") -> 0.019 | L30: =IF(J30=0,K30,IF(ISNUMBER(H30),H30/Assumptions!$B$8,"UNPRICED")) -> 0.019 | M30: =IF(J30=0,K30,IF(ISNUMBER(I30),I30/Assumptions!$B$9,"UNPRICED")) -> 0.019 | N30: First storage band; replication included in selected redundancy; retrieval and transaction meters are separate.
A31: Blob storage|Cool RA-GRS | B31: Blob storage | C31: Cool RA-GRS | D31: Storage | E31: GB-month | F31: Usage | G31: ='Price Evidence'!I17 -> 0.0425 | H31: UNPRICED | I31: UNPRICED | J31: 0 | K31: =IF(ISNUMBER(G31),G31,"UNPRICED") -> 0.0425 | L31: =IF(J31=0,K31,IF(ISNUMBER(H31),H31/Assumptions!$B$8,"UNPRICED")) -> 0.0425 | M31: =IF(J31=0,K31,IF(ISNUMBER(I31),I31/Assumptions!$B$9,"UNPRICED")) -> 0.0425 | N31: First storage band; replication included in selected redundancy; retrieval and transaction meters are separate.
A32: Blob storage writes|Hot LRS | B32: Blob storage writes | C32: Hot LRS | D32: Storage | E32: 10K operations | F32: Usage | G32: ='Price Evidence'!I18 -> 0.05 | H32: UNPRICED | I32: UNPRICED | J32: 0 | K32: =IF(ISNUMBER(G32),G32,"UNPRICED") -> 0.05 | L32: =IF(J32=0,K32,IF(ISNUMBER(H32),H32/Assumptions!$B$8,"UNPRICED")) -> 0.05 | M32: =IF(J32=0,K32,IF(ISNUMBER(I32),I32/Assumptions!$B$9,"UNPRICED")) -> 0.05 | N32: Meter units in Price Evidence. Review read/write meter for the selected storage tier.
... A43: ADLS storage reads|Hot LRS | B43: ADLS storage reads | C43: Hot LRS | D43: Storage | E43: 10K operations | F43: Usage | G43: ='Price Evidence'!I29 -> 0.005 | H43: UNPRICED | I43: UNPRICED | J43: 0 | K43: =IF(ISNUMBER(G43),G43,"UNPRICED") -> 0.005 | L43: =IF(J43=0,K43,IF(ISNUMBER(H43),H43/Assumptions!$B$8,"UNPRICED")) -> 0.005 | M43: =IF(J43=0,K43,IF(ISNUMBER(I43),I43/Assumptions!$B$9,"UNPRICED")) -> 0.005 | N43: Meter units in Price Evidence. Review read/write meter for the selected storage tier.
A44: File storage|Hot LRS | B44: File storage | C44: Hot LRS | D44: Storage | E44: GB-month | F44: Usage | G44: ='Price Evidence'!I30 -> 0.0287 | H44: UNPRICED | I44: UNPRICED | J44: 0 | K44: =IF(ISNUMBER(G44),G44,"UNPRICED") -> 0.0287 | L44: =IF(J44=0,K44,IF(ISNUMBER(H44),H44/Assumptions!$B$8,"UNPRICED")) -> 0.0287 | M44: =IF(J44=0,K44,IF(ISNUMBER(I44),I44/Assumptions!$B$9,"UNPRICED")) -> 0.0287
A45: Queue storage|Standard LRS | B45: Queue storage | C45: Standard LRS | D45: Storage | E45: GB-month | F45: Usage | G45: ='Price Evidence'!I31 -> 0.045 | H45: UNPRICED | I45: UNPRICED | J45: 0 | K45: =IF(ISNUMBER(G45),G45,"UNPRICED") -> 0.045 | L45: =IF(J45=0,K45,IF(ISNUMBER(H45),H45/Assumptions!$B$8,"UNPRICED")) -> 0.045 | M45: =IF(J45=0,K45,IF(ISNUMBER(I45),I45/Assumptions!$B$9,"UNPRICED")) -> 0.045
A46: Table storage|Standard LRS | B46: Table storage | C46: Standard LRS | D46: Storage | E46: GB-month | F46: Usage | G46: ='Price Evidence'!I32 -> 0.045 | H46: UNPRICED | I46: UNPRICED | J46: 0 | K46: =IF(ISNUMBER(G46),G46,"UNPRICED") -> 0.045 | L46: =IF(J46=0,K46,IF(ISNUMBER(H46),H46/Assumptions!$B$8,"UNPRICED")) -> 0.045 | M46: =IF(J46=0,K46,IF(ISNUMBER(I46),I46/Assumptions!$B$9,"UNPRICED")) -> 0.045
A47: File storage|Premium LRS - quote required | B47: File storage | C47: Premium LRS - quote required | D47: Storage | E47: provisioned GiB-month | F47: Usage | G47: UNPRICED | H47: UNPRICED | I47: UNPRICED | J47: 0 | K47: =IF(ISNUMBER(G47),G47,"UNPRICED") -> UNPRICED | L47: =IF(J47=0,K47,IF(ISNUMBER(H47),H47/Assumptions!$B$8,"UNPRICED")) -> UNPRICED | M47: =IF(J47=0,K47,IF(ISNUMBER(I47),I47/Assumptions!$B$9,"UNPRICED")) -> UNPRICED | N47: Premium Files requires provisioned capacity/IOPS/throughput sizing. Do not substitute standard hot storage.
A48: Key Vault|Standard | B48: Key Vault | C48: Standard | D48: Security | E48: 10K operations | F48: Usage | G48: ='Price Evidence'!I33 -> 0.03 | H48: UNPRICED | I48: UNPRICED | J48: 0 | K48: =IF(ISNUMBER(G48),G48,"UNPRICED") -> 0.03 | L48: =IF(J48=0,K48,IF(ISNUMBER(H48),H48/Assumptions!$B$8,"UNPRICED")) -> 0.03 | M48: =IF(J48=0,K48,IF(ISNUMBER(I48),I48/Assumptions!$B$9,"UNPRICED")) -> 0.03
A49: Logs|Analytics Logs | B49: Logs | C49: Analytics Logs | D49: Monitoring | E49: GB ingested | F49: Usage | G49: ='Price Evidence'!I34 -> 2.3 | H49: UNPRICED | I49: UNPRICED | J49: 0 | K49: =IF(ISNUMBER(G49),G49,"UNPRICED") -> 2.3 | L49: =IF(J49=0,K49,IF(ISNUMBER(H49),H49/Assumptions!$B$8,"UNPRICED")) -> 2.3 | M49: =IF(J49=0,K49,IF(ISNUMBER(I49),I49/Assumptions!$B$9,"UNPRICED")) -> 2.3 | N49: Gross paid-band ingestion. Free allowance ignored conservatively; Sentinel data is modeled separately to avoid double counting.
A50: Log retention|Analytics Logs | B50: Log retention | C50: Analytics Logs | D50: Monitoring | E50: GB-month beyond included retention | F50: Usage | G50: ='Price Evidence'!I35 -> 0.1 | H50: UNPRICED | I50: UNPRICED | J50: 0 | K50: =IF(ISNUMBER(G50),G50,"UNPRICED") -> 0.1 | L50: =IF(J50=0,K50,IF(ISNUMBER(H50),H50/Assumptions!$B$8,"UNPRICED")) -> 0.1 | M50: =IF(J50=0,K50,IF(ISNUMBER(I50),I50/Assumptions!$B$9,"UNPRICED")) -> 0.1
